Workbook
Name Arial: #REF!

Sheet Dashboard
B1: CABLE INSTALLATION OVERVIEW | P1: ="Total: "&TEXT('system by total'!H2,"#,##0")&" cables" -> Total: 2,627 cables
B2: TRACK PROGRESS | CUT · PULL · CONNECT · TEST
B5: SELECT SYSTEM ▼ | O5: CONTRACTORS
B6: 133 | D6: =Dash_Data!T50 -> 133 – EM.POWER DISTRIBUTION 220-240V | Q6: HDC | R6: NAUTICS | S6: ST
B8: TOTAL CABLES | E8: TOTAL CABLE LENGTH | H8: CUT % | K8: PULLED % | N8: CONNECTION % | Q8: CWC-MEGGER %
B9: ='system by total'!H2 -> 2627 | E9: =TỔNG!H4 -> 65233 | H9: ='system by total'!D2 -> 0.85915493 | K9: ='system by total'!E2 -> 0.70194138 | N9: ='system by total'!F2 -> 0.10677579 | Q9: ='system by total'!G2 -> 0
B11: =COUNTA('system by total'!B3:B89)&" systems" -> 87 systems | E11: =" HDC · NAUTICS · ST" -> HDC · NAUTICS · ST | H11: ="By length: "&TEXT(TỔNG!I3,"0.0%") -> By length: 91.6% | K11: ="By length: "&TEXT(TỔNG!I5,"0.0%") -> By length: 76.2% | N11: ="By length: "&TEXT(TỔNG!I7,"0.0%") -> By length: 10.7% | Q11: ="By cable count" -> By cable count
B49: Selected system – stage progress
B51: System | D51: =Dash_Data!T50 -> 133 – EM.POWER DISTRIBUTION 220-240V
B52: Cables in system | D52: =Dash_Data!T51 -> 18
B54: Stage | D54: HDC | F54: NAUTICS | H54: ST | J54: All
B55: Cut | D55: =Dash_Data!T44 -> 1 | F55: =Dash_Data!U44 -> 1 | H55: =Dash_Data!V44 -> 0 | J55: =Dash_Data!W44 -> 1
B56: Pulled | D56: =Dash_Data!T45 -> 0.76923077 | F56: =Dash_Data!U45 -> 1 | H56: =Dash_Data!V45 -> 0 | J56: =Dash_Data!W45 -> 0.83333333
B57: Connection | D57: =Dash_Data!T46 -> 0.11538462 | F57: =Dash_Data!U46 -> 0.5 | H57: =Dash_Data!V46 -> 0 | J57: =Dash_Data!W46 -> 0.22222222
B58: CWC-Megger | D58: =Dash_Data!T47 -> 0 | F58: =Dash_Data!U47 -> 0 | H58: =Dash_Data!V47 -> 0 | J58: =Dash_Data!W47 -> 0
B60: A contractor not working on the selected system shows 0%.
L67: Top 10 systems – details
L68: Largest backlog first: cables × (1 − Pulled %)
L69: # | M69: System | N69: Cables | O69: Cut % | P69: Pulled % | R69: To pull
L70: 1 | M70: =Dash_Data!U31 -> 461 | N70: =Dash_Data!W31 -> 321 | O70: =Dash_Data!X31 -> 0.4423676 | P70: =Dash_Data!Y31 -> 0.034267913 | R70: =Dash_Data!T31 -> 310
L71: 2 | M71: =Dash_Data!U32 -> 401.2 | N71: =Dash_Data!W32 -> 46 | O71: =Dash_Data!X32 -> 0.82608696 | P71: =Dash_Data!Y32 -> 0.41304348 | R71: =Dash_Data!T32 -> 27
L72: 3 | M72: =Dash_Data!U33 -> 222 | N72: =Dash_Data!W33 -> 29 | O72: =Dash_Data!X33 -> 1 | P72: =Dash_Data!Y33 -> 0.13793103 | R72: =Dash_Data!T33 -> 25
L73: 4 | M73: =Dash_Data!U34 -> 416 | N73: =Dash_Data!W34 -> 45 | O73: =Dash_Data!X34 -> 0.53333333 | P73: =Dash_Data!Y34 -> 0.44444444 | R73: =Dash_Data!T34 -> 25
L74: 5 | M74: =Dash_Data!U35 -> 306 | N74: =Dash_Data!W35 -> 57 | O74: =Dash_Data!X35 -> 0.96491228 | P74: =Dash_Data!Y35 -> 0.59649123 | R74: =Dash_Data!T35 -> 23
L75: 6 | M75: =Dash_Data!U36 -> 721 | N75: =Dash_Data!W36 -> 31 | O75: =Dash_Data!X36 -> 0.74193548 | P75: =Dash_Data!Y36 -> 0.35483871 | R75: =Dash_Data!T36 -> 20
L76: 7 | M76: =Dash_Data!U37 -> 412 | N76: =Dash_Data!W37 -> 84 | O76: =Dash_Data!X37 -> 0.92857143 | P76: =Dash_Data!Y37 -> 0.77380952 | R76: =Dash_Data!T37 -> 19
L77: 8 | M77: =Dash_Data!U38 -> 581 | N77: =Dash_Data!W38 -> 19 | O77: =Dash_Data!X38 -> 0.52631579 | P77: =Dash_Data!Y38 -> 0.15789474 | R77: =Dash_Data!T38 -> 16
L78: 9 | M78: =Dash_Data!U39 -> 101.2 | N78: =Dash_Data!W39 -> 27 | O78: =Dash_Data!X39 -> 0.66666667 | P78: =Dash_Data!Y39 -> 0.44444444 | R78: =Dash_Data!T39 -> 15
L79: 10 | M79: =Dash_Data!U40 -> 304.1 | N79: =Dash_Data!W40 -> 29 | O79: =Dash_Data!X40 -> 0.62068966 | P79: =Dash_Data!Y40 -> 0.51724138 | R79: =Dash_Data!T40 -> 14

Sheet hdc
A1: System | B1: Cable ID | C1: Cut | D1: Pulled | E1: Connection | F1: CWC- Megger | G1: Cable Type | H1: Segregation | I1: Design Length(m) | J1: Cable Cutting Length | K1: From Device | L1: From Device Description | M1: From Device Area | N1: From Device Area Description | O1: To Device | P1: To Device Description | Q1: To Device Off Route Length (m) | R1: To Device Area | S1: To Device Area Description | T1: Cable Route | U1: Cable Notes | V1: Local/Not Local Cables | W1: WK/REV.REASON | X1: From Node | Y1: To Node
A2: 101.1 | B2: 101.1W0001 | C2: 1 | D2: 1 | E2: 1 | G2: C 3X50 | H2: S1 | I2: 17.18 | J2: =ROUNDUP(I2,0) -> 18 | K2: (+10P0.2) | L2: 10P0.2 MAIN SWITCHBOARD DIESEL GENERATOR FWD | M2: 2266 | N2: SWITCHBOARD ROOM / LOCAL TABLEAUX | O2: (=101.1++1060+-101.1U07) | P2: DIESEL GENERATOR FORE | Q2: 3 | R2: 1060 | S2: ENGINE ROOM / SALLE DES MACHINES | T2: 10P0.2,226612013P15-10P0.2,1060P013X27N,1060P013X19N,1060P014X07N,1060P014X05N,1060P013X03N,1060P012X07N | V2: NOT LOCAL CABLE | W2: WK39/2024 NEW CABLE | X2: 10P0.2 | Y2: 1060P012X07N
A3: 101.1 | B3: 101.1W0002 | C3: 1 | D3: 1 | E3: 1 | G3: C 3X50 | H3: S1 | I3: 17.18 | J3: =ROUNDUP(I3,0) -> 18 | K3: (+10P0.2) | L3: 10P0.2 MAIN SWITCHBOARD DIESEL GENERATOR FWD | M3: 2266 | N3: SWITCHBOARD ROOM / LOCAL TABLEAUX | O3: (=101.1++1060+-101.1U07) | P3: DIESEL GENERATOR FORE | Q3: 3 | R3: 1060 | S3: ENGINE ROOM / SALLE DES MACHINES | T3: 10P0.2,226612013P15-10P0.2,1060P013X27N,1060P013X19N,1060P014X07N,1060P014X05N,1060P013X03N,1060P012X07N | V3: NOT LOCAL CABLE | W3: WK39/2024 NEW CABLE | X3: 10P0.2 | Y3: 1060P012X07N
A4: 101.1 | B4: 101.1W0003 | C4: 1 | D4: 1 | E4: 1 | G4: C 3X50 | H4: S1 | I4: 17.18 | J4: =ROUNDUP(I4,0) -> 18 | K4: (+10P0.2) | L4: 10P0.2 MAIN SWITCHBOARD DIESEL GENERATOR FWD | M4: 2266 | N4: SWITCHBOARD ROOM / LOCAL TABLEAUX | O4: (=101.1++1060+-101.1U07) | P4: DIESEL GENERATOR FORE | Q4: 3 | R4: 1060 | S4: ENGINE ROOM / SALLE DES MACHINES | T4: 10P0.2,226612013P15-10P0.2,1060P013X27N,1060P013X19N,1060P014X07N,1060P014X05N,1060P013X03N,1060P012X07N | V4: NOT LOCAL CABLE | W4: WK39/2024 NEW CABLE | X4: 10P0.2 | Y4: 1060P012X07N
A5: 101.1 | B5: 101.1W0004 | C5: 1 | D5: 1 | E5: 1 | G5: C 3X2.5 | H5: S1 | I5: 18.07 | J5: =ROUNDUP(I5,0) -> 19 | K5: (+10P0.8) | L5: 10P0.8 MAIN SWITCHBOARD 230VAC CONSUMERS | M5: 2266 | N5: SWITCHBOARD ROOM / LOCAL TABLEAUX | O5: (=101.1++1060+-101.1U07) | P5: DIESEL GENERATOR FORE | Q5: 3 | R5: 1060 | S5: ENGINE ROOM / SALLE DES MACHINES | T5: 10P0.8,226612013P20-10P0.8,1060P013X26N,1060P013X25N,1060P013X19N,1060P014X07N,1060P014X05N,1060P013X03N,1060P012X07N | V5: NOT LOCAL CABLE | W5: WK39/2024 NEW CABLE | X5: 10P0.8 | Y5: 1060P012X07N
A6: 101.1 | B6: 101.1W0005 | C6: 1 | D6: 1 | E6: 1 | G6: C 3X1.5 | H6: S1 | I6: 17.18 | J6: =ROUNDUP(I6,0) -> 18 | K6: (+10P0.2) | L6: 10P0.2 MAIN SWITCHBOARD DIESEL GENERATOR FWD | M6: 2266 | N6: SWITCHBOARD ROOM / LOCAL TABLEAUX | O6: (=101.1++1060+-101.1U07) | P6: DIESEL GENERATOR FORE | Q6: 3 | R6: 1060 | S6: ENGINE ROOM / SALLE DES MACHINES | T6: 10P0.2,226612013P15-10P0.2,1060P013X27N,1060P013X19N,1060P014X07N,1060P014X05N,1060P013X03N,1060P012X07N | V6: NOT LOCAL CABLE | W6: WK39/2024 NEW CABLE | X6: 10P0.2 | Y6: 1060P012X07N
A7: 101.1 | B7: 101.1W0009 | C7: 1 | G7: FLEX 1X120 | H7: S1 | I7: 13.6 | J7: =ROUNDUP(I7,0) -> 14 | K7: (+14E1) | L7: "14E1" ME'S & DG'S START BATTERY COMUTATION PANEL | M7: 1060 | N7: ENGINE ROOM / SALLE DES MACHINES | O7: (=101.1++1060+-101.1U07) | P7: DIESEL GENERATOR FORE | Q7: 3 | R7: 1060 | S7: ENGINE ROOM / SALLE DES MACHINES | T7: 1060P011X07N,1060P012X01N,1060P013X03N,1060P012X07N | V7: LOCAL | W7: WK39/2024 NEW CABLE | X7: 1060P011X07N | Y7: 1060P012X07N
A8: 101.1 | B8: 101.1W0010 | C8: 1 | G8: FLEX 1X120 | H8: S1 | I8: 13.6 | J8: =ROUNDUP(I8,0) -> 14 | K8: (+14E1) | L8: "14E1" ME'S & DG'S START BATTERY COMUTATION PANEL | M8: 1060 | N8: ENGINE ROOM / SALLE DES MACHINES | O8: (=101.1++1060+-101.1U07) | P8: DIESEL GENERATOR FORE | Q8: 3 | R8: 1060 | S8: ENGINE ROOM / SALLE DES MACHINES | T8: 1060P011X07N,1060P012X01N,1060P013X03N,1060P012X07N | V8: LOCAL | W8: WK39/2024 NEW CABLE | X8: 1060P011X07N | Y8: 1060P012X07N
A9: 101.1 | B9: 101.1W0012 | C9: 1 | G9: C 2X2.5 | H9: S1 | I9: 25.17 | J9: =ROUNDUP(I9,0) -> 26 | K9: (=101.1++1060+-101.1U01) | L9: DIESEL GENERATOR FORE PANEL | M9: 1060 | N9: ENGINE ROOM / SALLE DES MACHINES | O9: (=101.1++1060+-101.1U02) | P9: SCR PANEL DIESEL GENERATOR FORE 10610E03 | Q9: 3 | R9: 1060 | S9: ENGINE ROOM / SALLE DES MACHINES | T9: 1060P012X01N,1060P014X05N,1060P014X07N,1060P013X19N,1060P013X22N,1060S013X03N,1060S014X02N,1060S012X02N,1060S012X16N,1060S012X14N,1060S012X13N | V9: LOCAL | W9: WK39/2024 NEW CABLE | X9: 1060P012X01N | Y9: 1060S012X13N
A10: 101.1 | B10: 101.1W0015 | C10: 1 | G10: C 2X2.5 | H10: S1 | I10: 11.12 | J10: =ROUNDUP(I10,0) -> 12 | K10: (+14E1) | L10: "14E1" ME'S & DG'S START BATTERY COMUTATION PANEL | M10: 1060 | N10: ENGINE ROOM / SALLE DES MACHINES | O10: (=101.1++1060+-101.1U01) | P10: DIESEL GENERATOR FORE PANEL | Q10: 4 | R10: 1060 | S10: ENGINE ROOM / SALLE DES MACHINES | T10: 1060P011X07N,1060P012X01N | V10: LOCAL | W10: WK39/2024 NEW CABLE | X10: 1060P011X07N | Y10: 1060P012X01N
A11: 101.1 | B11: 101.1W0016 | C11: 1 | D11: 1 | E11: 1 | G11: C 2X2.5 | H11: S1 | I11: 28.25 | J11: =ROUNDUP(I11,0) -> 29 | K11: (+14E4) | L11: 14E4 24VDC SERVICE DISTRIBUTION PANEL | M11: 2266 | N11: SWITCHBOARD ROOM / LOCAL TABLEAUX | O11: (=101.1++1060+-101.1U01) | P11: DIESEL GENERATOR FORE PANEL | Q11: 4 | R11: 1060 | S11: ENGINE ROOM / SALLE DES MACHINES | T11: 2266P011X21N,226612013P11,1060P013X26N,1060P013X25N,1060P013X19N,1060P014X07N,1060P014X05N,1060P012X01N | V11: NOT LOCAL CABLE | W11: WK39/2024 NEW CABLE | X11: 2266P011X21N | Y11: 1060P012X01N
A12: 101.1 | B12: 101.1W0028 | C12: 1 | D12: 1 | G12: C+FR+SH 2X1.5 | H12: S1 | I12: 82.47 | J12: =ROUNDUP(I12,0) -> 83 | K12: (+42DF.7) | L12: 42DF.7 CENTRAL CONSOLE | M12: 4032 | N12: WHEELHOUSE / TIMONERIE | O12: (=101.1++1060+-101.1U01) | P12: DIESEL GENERATOR FORE PANEL | Q12: 4 | R12: 1060 | S12: ENGINE ROOM / SALLE DES MACHINES | T12: 4032P032X13N,4032S031X49N,4032P031X36N,4032S031X06N,304033030P11,3040P027X05N,3040S026X08N,3040S027X03N,3040S027X07N,204023027S11,2040S027X02N,2040S023X01N,2040S018X01N,204022015S11,2165S015X03N,2165S012X03N,216512012S11,1060S012X16N,1060S012X02N,1060S014X02N,1060S013X03N,1060P013X22N,1060P013X19N,1060P014X07N,1060P014X05N,1060P012X01N | V12: NOT LOCAL CABLE | W12: WK39/2024 NEW CABLE | X12: 4032P032X13N | Y12: 1060P012X01N
A13: 101.1 | B13: 101.1W0029 | C13: 1 | D13: 1 | G13: C+SH 3X2.5 | H13: S1 | I13: 75.14 | J13: =ROUNDUP(I13,0) -> 76 | K13: (+42DF.7) | L13: 42DF.7 CENTRAL CONSOLE | M13: 4032 | N13: WHEELHOUSE / TIMONERIE | O13: (=101.1++1060+-101.1U01) | P13: DIESEL GENERATOR FORE PANEL | Q13: 4 | R13: 1060 | S13: ENGINE ROOM / SALLE DES MACHINES | T13: 4032P032X13N,4032S031X06N,304033030P11,3040P027X05N,3040P024X02N,3040P020X02N,3040P019X04N,3040P018X11N,3040P017X04N,3040P017X09N,204023018P11,2040P018X01N,2040P018X22N,226622015P11,227222011P11,2272P010X01N,2272P009X01N,2272P009X08N,106012011P11,1060P012X21N,1060P013X27N,1060P013X19N,1060P014X07N,1060P014X05N,1060P012X01N | V13: NOT LOCAL CABLE | W13: WK39/2024 NEW CABLE | X13: 4032P032X13N | Y13: 1060P012X01N
A14: 101.2 | B14: 101.2W0001 | C14: 1 | D14: 1 | G14: C 3X50 | H14: S1 | I14: 18.21 | J14: =ROUNDUP(I14,0) -> 19 | K14: (+10P0.6) | L14: 10P0.6 MAIN SWITCHBOARD DIESEL GENERATOR AFT | M14: 2266 | N14: SWITCHBOARD ROOM / LOCAL TABLEAUX | O14: (=101.2++1060+-101.2U07) | P14: DIESEL GENERATOR AFT | Q14: 3 | R14: 1060 | S14: ENGINE ROOM / SALLE DES MACHINES | T14: 10P0.6,226612013P14-10P0.6,1060P013X25N,1060P013X19N,1060P014X07N,1060P014X05N,1060P012X01N,1060P011X04N,1060P010X01N | V14: NOT LOCAL CABLE | W14: WK39/2024 NEW CABLE | X14: 10P0.6 | Y14: 1060P010X01N
A15: 101.2 | B15: 101.2W0002 | C15: 1 | D15: 1 | G15: C 3X50 | H15: S1 | I15: 18.21 | J15: =ROUNDUP(I15,0) -> 19 | K15: (+10P0.6) | L15: 10P0.6 MAIN SWITCHBOARD DIESEL GENERATOR AFT | M15: 2266 | N15: SWITCHBOARD ROOM / LOCAL TABLEAUX | O15: (=101.2++1060+-101.2U07) | P15: DIESEL GENERATOR AFT | Q15: 3 | R15: 1060 | S15: ENGINE ROOM / SALLE DES MACHINES | T15: 10P0.6,226612013P14-10P0.6,1060P013X25N,1060P013X19N,1060P014X07N,1060P014X05N,1060P012X01N,1060P011X04N,1060P010X01N | V15: NOT LOCAL CABLE | W15: WK39/2024 NEW CABLE | X15: 10P0.6 | Y15: 1060P010X01N
A16: 101.2 | B16: 101.2W0003 | C16: 1 | D16: 1 | G16: C 3X50 | H16: S1 | I16: 18.21 | J16: =ROUNDUP(I16,0) -> 19 | K16: (+10P0.6) | L16: 10P0.6 MAIN SWITCHBOARD DIESEL GENERATOR AFT | M16: 2266 | N16: SWITCHBOARD ROOM / LOCAL TABLEAUX | O16: (=101.2++1060+-101.2U07) | P16: DIESEL GENERATOR AFT | Q16: 3 | R16: 1060 | S16: ENGINE ROOM / SALLE DES MACHINES | T16: 10P0.6,226612013P14-10P0.6,1060P013X25N,1060P013X19N,1060P014X07N,1060P014X05N,1060P012X01N,1060P011X04N,1060P010X01N | V16: NOT LOCAL CABLE | W16: WK39/2024 NEW CABLE | X16: 10P0.6 | Y16: 1060P010X01N
A17: 101.2 | B17: 101.2W0004 | C17: 1 | D17: 1 | E17: 1 | G17: C 3X2.5 | H17: S1 | I17: 20.43 | J17: =ROUNDUP(I17,0) -> 21 | K17: (+10P0.8) | L17: 10P0.8 MAIN SWITCHBOARD 230VAC CONSUMERS | M17: 2266 | N17: SWITCHBOARD ROOM / LOCAL TABLEAUX | O17: (=101.2++1060+-101.2U07) | P17: DIESEL GENERATOR AFT | Q17: 3 | R17: 1060 | S17: ENGINE ROOM / SALLE DES MACHINES | T17: 10P0.8,226612013P20-10P0.8,1060P013X26N,1060P013X25N,1060P013X19N,1060P014X07N,1060P014X05N,1060P012X01N,1060P011X04N,1060P010X01N | V17: NOT LOCAL CABLE | W17: WK39/2024 NEW CABLE | X17: 10P0.8 | Y17: 1060P010X01N
A18: 101.2 | B18: 101.2W0005 | C18: 1 | D18: 1 | G18: C 3X1.5 | H18: S1 | I18: 18.21 | J18: =ROUNDUP(I18,0) -> 19 | K18: (+10P0.6) | L18: 10P0.6 MAIN SWITCHBOARD DIESEL GENERATOR AFT | M18: 2266 | N18: SWITCHBOARD ROOM / LOCAL TABLEAUX | O18: (=101.2++1060+-101.2U07) | P18: DIESEL GENERATOR AFT | Q18: 3 | R18: 1060 | S18: ENGINE ROOM / SALLE DES MACHINES | T18: 10P0.6,226612013P14-10P0.6,1060P013X25N,1060P013X19N,1060P014X07N,1060P014X05N,1060P012X01N,1060P011X04N,1060P010X01N | V18: NOT LOCAL CABLE | W18: WK39/2024 NEW CABLE | X18: 10P0.6 | Y18: 1060P010X01N
A19: 101.2 | B19: 101.2W0009 | C19: 1 | G19: FLEX 1X120 | H19: S1 | I19: 11 | J19: =ROUNDUP(I19,0) -> 11 | K19: (+14E1) | L19: "14E1" ME'S & DG'S START BATTERY COMUTATION PANEL | M19: 1060 | N19: ENGINE ROOM / SALLE DES MACHINES | O19: (=101.2++1060+-101.2U07) | P19: DIESEL GENERATOR AFT | Q19: 3 | R19: 1060 | S19: ENGINE ROOM / SALLE DES MACHINES | T19: 1060P011X07N,1060P011X04N,1060P010X01N | V19: LOCAL | W19: WK39/2024 NEW CABLE | X19: 1060P011X07N | Y19: 1060P010X01N
A20: 101.2 | B20: 101.2W0010 | C20: 1 | G20: FLEX 1X120 | H20: S1 | I20: 11 | J20: =ROUNDUP(I20,0) -> 11 | K20: (+14E1) | L20: "14E1" ME'S & DG'S START BATTERY COMUTATION PANEL | M20: 1060 | N20: ENGINE ROOM / SALLE DES MACHINES | O20: (=101.2++1060+-101.2U07) | P20: DIESEL GENERATOR AFT | Q20: 3 | R20: 1060 | S20: ENGINE ROOM / SALLE DES MACHINES | T20: 1060P011X07N,1060P011X04N,1060P010X01N | V20: LOCAL | W20: WK39/2024 NEW CABLE | X20: 1060P011X07N | Y20: 1060P010X01N
A21: 101.2 | B21: 101.2W0012 | C21: 1 | D21: 1 | G21: C 2X2.5 | H21: S1 | I21: 14.79 | J21: =ROUNDUP(I21,0) -> 15 | K21: (=101.2++1060+-101.2U01) | L21: DIESEL GENERATOR AFT PANEL | M21: 1060 | N21: ENGINE ROOM / SALLE DES MACHINES | O21: (=101.2++1060+-101.2U02) | P21: SCR PANEL DIESEL GENERATOR AFT 10610E04 | Q21: 0 | R21: 1060 | S21: ENGINE ROOM / SALLE DES MACHINES | T21: OFF ROUTE | V21: LOCAL | W21: WK10/2025/UPDATE CABLE LENGHT-PVN COMM R1.05 | X21: OFF ROUTE | Y21: OFF ROUTE
A22: 101.2 | B22: 101.2W0015 | C22: 1 | G22: C 2X2.5 | H22: S1 | I22: 25.1 | J22: =ROUNDUP(I22,0) -> 26 | K22: (+14E1) | L22: "14E1" ME'S & DG'S START BATTERY COMUTATION PANEL | M22: 1060 | N22: ENGINE ROOM / SALLE DES MACHINES | O22: (=101.2++1060+-101.2U01) | P22: DIESEL GENERATOR AFT PANEL | Q22: 3.5 | R22: 1060 | S22: ENGINE ROOM / SALLE DES MACHINES | T22: 1060P011X07N,1060P012X01N,1060P014X05N,1060P014X07N,1060P013X19N,1060P013X27N,1060P012X21N,1060P012X18N,1060P009X04N,1060P009X05N,1060S009X03N | V22: LOCAL | W22: WK39/2024 NEW CABLE | X22: 1060P011X07N | Y22: 1060S009X03N
A23: 101.2 | B23: 101.2W0016 | C23: 1 | G23: C 2X2.5 | H23: S1 | I23: 25.41 | J23: =ROUNDUP(I23,0) -> 26 | K23: (+14E4) | L23: 14E4 24VDC SERVICE DISTRIBUTION PANEL | M23: 2266 | N23: SWITCHBOARD ROOM / LOCAL TABLEAUX | O23: (=101.2++1060+-101.2U01) | P23: DIESEL GENERATOR AFT PANEL | Q23: 3.5 | R23: 1060 | S23: ENGINE ROOM / SALLE DES MACHINES | T23: 2266P011X21N,227222011P11,2272P010X01N,2272P009X01N,2272P009X08N,106012011P11,1060P012X21N,1060P012X18N,1060P009X04N,1060P009X05N,1060S009X03N | V23: NOT LOCAL CABLE | W23: WK39/2024 NEW CABLE | X23: 2266P011X21N | Y23: 1060S009X03N
A24: 101.2 | B24: 101.2W0028 | C24: 1 | G24: C+FR+SH 2X1.5 | H24: S1 | I24: 57.43 | J24: =ROUNDUP(I24,0) -> 58 | K24: (+42DF.7) | L24: 42DF.7 CENTRAL CONSOLE | M24: 4032 | N24: WHEELHOUSE / TIMONERIE | O24: (=101.2++1060+-101.2U01) | P24: DIESEL GENERATOR AFT PANEL | Q24: 3.5 | R24: 1060 | S24: ENGINE ROOM / SALLE DES MACHINES | T24: 4032P032X13N,4032S031X06N,4032S031X05N,4032S031X03N,304033030S11,3040S027X02N,3040S027X03N,3040S023X01N,3040S021X02N,3040S017X03N,316333015S11,3163S014X02N,3163S012X04N,3163S012X06N,216523012S11,216512012S11,1060S012X16N,1060S009X02N,1060S009X03N | V24: NOT LOCAL CABLE | W24: WK39/2024 NEW CABLE | X24: 4032P032X13N | Y24: 1060S009X03N
A25: 101.2 | B25: 101.2W0029 | C25: 1 | G25: C+SH 3X2.5 | H25: S1 | I25: 57.43 | J25: =ROUNDUP(I25,0) -> 58 | K25: (+42DF.7) | L25: 42DF.7 CENTRAL CONSOLE | M25: 4032 | N25: WHEELHOUSE / TIMONERIE | O25: (=101.2++1060+-101.2U01) | P25: DIESEL GENERATOR AFT PANEL | Q25: 3.5 | R25: 1060 | S25: ENGINE ROOM / SALLE DES MACHINES | T25: 4032P032X13N,4032S031X06N,4032S031X05N,4032S031X03N,304033030S11,3040S027X02N,3040S027X03N,3040S023X01N,3040S021X02N,3040S017X03N,316333015S11,3163S014X02N,3163S012X04N,3163S012X06N,216523012S11,216512012S11,1060S012X16N,1060S009X02N,1060S009X03N | V25: NOT LOCAL CABLE | W25: WK39/2024 NEW CABLE | X25: 4032P032X13N | Y25: 1060S009X03N
A26: 102 | B26: 102W0003 | C26: 1 | D26: 1 | G26: C 2X2.5 | H26: S1 | I26: 14.75 | J26: =ROUNDUP(I26,0) -> 15 | K26: (+14E3) | L26: 14E3 EDG START BATTERY PANEL | M26: 4262 | N26: EMG. GENSET / GROUPE DE SECOURS | O26: (=102++4262+-102U01) | P26: EMERGENCY GENERATOR PANEL | Q26: 2.5 | R26: 4262 | S26: EMG. GENSET / GROUPE DE SECOURS | T26: 4262P012X02N,4262P014X01N,4262P015X03N,4262P013X06N | V26: LOCAL | W26: WK39/2024 NEW CABLE | X26: 4262P012X02N | Y26: 4262P013X06N
A27: 102 | B27: 102W0004 | C27: 1 | G27: C 3X2.5 | H27: S1 | I27: 10.71 | J27: =ROUNDUP(I27,0) -> 11 | K27: (+12EP0.2) | L27: 12EP0.2 EMERGENCY SWITCHBOARD CONSUMERS 3X230V 50HZ | M27: 4262 | N27: EMG. GENSET / GROUPE DE SECOURS | O27: (=102++4262+-102U02) | P27: EMERGENCY GENERATOR | Q27: 0 | R27: 4262 | S27: EMG. GENSET / GROUPE DE SECOURS | T27: OFF ROUTE | V27: LOCAL | W27: WK39/2024 NEW CABLE | X27: OFF ROUTE | Y27: OFF ROUTE
A28: 102 | B28: 102W0005 | C28: 1 | G28: FLEX 1X50 | H28: S1 | I28: 13.73 | J28: =ROUNDUP(I28,0) -> 14 | K28: (+14E3) | L28: 14E3 EDG START BATTERY PANEL | M28: 4262 | N28: EMG. GENSET / GROUPE DE SECOURS | O28: (=102++4262+-102U02) | P28: EMERGENCY GENERATOR | Q28: 1.5 | R28: 4262 | S28: EMG. GENSET / GROUPE DE SECOURS | T28: 4262P012X02N,4262P014X01N,4262P015X03N,4262P013X06N | V28: LOCAL | W28: WK39/2024 NEW CABLE | X28: 4262P012X02N | Y28: 4262P013X06N
A29: 102 | B29: 102W0006 | C29: 1 | G29: FLEX 1X50 | H29: S1 | I29: 13.73 | J29: =ROUNDUP(I29,0) -> 14 | K29: (+14E3) | L29: 14E3 EDG START BATTERY PANEL | M29: 4262 | N29: EMG. GENSET / GROUPE DE SECOURS | O29: (=102++4262+-102U02) | P29: EMERGENCY GENERATOR | Q29: 1.5 | R29: 4262 | S29: EMG. GENSET / GROUPE DE SECOURS | T29: 4262P012X02N,4262P014X01N,4262P015X03N,4262P013X06N | V29: LOCAL | W29: WK39/2024 NEW CABLE | X29: 4262P012X02N | Y29: 4262P013X06N
A30: 102 | B30: 102W0008 | C30: 1 | D30: 1 | G30: C 3X1.5 | H30: S1 | I30: 7.69 | J30: =ROUNDUP(I30,0) -> 8 | K30: (+12EP0.1) | L30: 12EP0.1 EMERGENCY SWITCHBOARD EDG 52KW / MSB TRANSFER LINE / CONSUMERS 3X400V 50HZ | M30: 4262 | N30: EMG. GENSET / GROUPE DE SECOURS | O30: (=102++4262+-102U02) | P30: EMERGENCY GENERATOR | Q30: 1.5 | R30: 4262 | S30: EMG. GENSET / GROUPE DE SECOURS | T30: 12EP0.1,4262P013X06N | V30: LOCAL | W30: WK39/2024 NEW CABLE | X30: 12EP0.1 | Y30: 4262P013X06N
A31: 102 | B31: 102W0009 | C31: 1 | G31: C 3X70 | H31: S1 | I31: 5.65 | J31: =ROUNDUP(I31,0) -> 6 | K31: (+12EP0.1) | L31: 12EP0.1 EMERGENCY SWITCHBOARD EDG 52KW / MSB TRANSFER LINE / CONSUMERS 3X400V 50HZ | M31: 4262 | N31: EMG. GENSET / GROUPE DE SECOURS | O31: (=102++4262+-102U02) | P31: EMERGENCY GENERATOR | Q31: 1.5 | R31: 4262 | S31: EMG. GENSET / GROUPE DE SECOURS | T31: 12EP0.1,4262P013X06N | V31: LOCAL | W31: WK03/2025/UPDATE CABLE TYPE R1.01 | X31: 12EP0.1 | Y31: 4262P013X06N
A32: 102 | B32: 102W0013 | C32: 1 | D32: 1 | G32: C+SH 3X1.5 | H32: S1 | I32: 11.28 | J32: =ROUNDUP(I32,0) -> 12 | K32: (+12EP0.1) | L32: 12EP0.1 EMERGENCY SWITCHBOARD EDG 52KW / MSB TRANSFER LINE / CONSUMERS 3X400V 50HZ | M32: 4262 | N32: EMG. GENSET / GROUPE DE SECOURS | O32: (+12EP0.2) | P32: 12EP0.2 EMERGENCY SWITCHBOARD CONSUMERS 3X230V 50HZ | Q32: 4 | R32: 4262 | S32: EMG. GENSET / GROUPE DE SECOURS | T32: 12EP0.1,326434015P11,3264P015X05N,326434015P12,12EP0.2 | V32: LOCAL | W32: WK03/2025/NEW CABLE R1.01 | X32: 12EP0.1 | Y32: 12EP0.2
A33: 102 | B33: 102W0014 | C33: 1 | D33: 1 | E33: 1 | G33: C 2X2.5 | H33: S1 | I33: 27.57 | J33: =ROUNDUP(I33,0) -> 28 | K33: (+14E4) | L33: 14E4 24VDC SERVICE DISTRIBUTION PANEL | M33: 2266 | N33: SWITCHBOARD ROOM / LOCAL TABLEAUX | O33: (=102++4262+-102U01) | P33: EMERGENCY GENERATOR PANEL | Q33: 2.5 | R33: 4262 | S33: EMG. GENSET / GROUPE DE SECOURS | T33: 2266P011X21N,226623013P11,3264P012X08N,3264P012X04N,3264P015X01N,326434015P11,4262P013X06N | V33: NOT LOCAL CABLE | W33: WK03/2025/NEW CABLE R1.01 | X33: 2266P011X21N | Y33: 4262P013X06N
A34: 105 | B34: 105W0001 | C34: 1 | D34: 1 | E34: 1 | G34: C 3X50 | H34: S1 | I34: 30.63 | J34: =ROUNDUP(I34,0) -> 31 | K34: (+10P0.1) | L34: 10P0.1 MAIN SWITCHBOARD 400VAC CONSUMERS | M34: 2266 | N34: SWITCHBOARD ROOM / LOCAL TABLEAUX | O34: (+10SC1) | P34: 10SC1 SHORE CONNECTION BOX 250A | Q34: 3 | R34: 4161 | S34: AIR TREATMENT / CENTR. TRAIT. AIR | T34: 10P0.1,226612013P17-10P0.1,1060P013X27N,1060P013X19N,1060P013X22N,1060S013X03N,1060S014X02N,1060S012X02N,1060S012X16N,216512012S11,216523012S11,3163S012X06N,3163S012X04N,3163S011X01N,416134012S11,4161S012X03N | V34: NOT LOCAL CABLE | W34: WK39/2024 NEW CABLE | X34: 10P0.1 | Y34: 4161S012X03N
A35: 105 | B35: 105W0002 | C35: 1 | D35: 1 | E35: 1 | G35: C 3X50 | H35: S1 | I35: 30.63 | J35: =ROUNDUP(I35,0) -> 31 | K35: (+10P0.1) | L35: 10P0.1 MAIN SWITCHBOARD 400VAC CONSUMERS | M35: 2266 | N35: SWITCHBOARD ROOM / LOCAL TABLEAUX | O35: (+10SC1) | P35: 10SC1 SHORE CONNECTION BOX 250A | Q35: 3 | R35: 4161 | S35: AIR TREATMENT / CENTR. TRAIT. AIR | T35: 10P0.1,226612013P17-10P0.1,1060P013X27N,1060P013X19N,1060P013X22N,1060S013X03N,1060S014X02N,1060S012X02N,1060S012X16N,216512012S11,216523012S11,3163S012X06N,3163S012X04N,3163S011X01N,416134012S11,4161S012X03N | V35: NOT LOCAL CABLE | W35: WK39/2024 NEW CABLE | X35: 10P0.1 | Y35: 4161S012X03N
A36: 105 | B36: 105W0003 | C36: 1 | D36: 1 | G36: C 3X95 | H36: S1 | I36: 28.44 | J36: =ROUNDUP(I36,0) -> 29 | K36: (+10P0.7) | L36: 10P0.7 MAIN SWITCHBOARD 400VAC CONSUMERS | M36: 2266 | N36: SWITCHBOARD ROOM / LOCAL TABLEAUX | O36: (+10SC2) | P36: 10SC2 SHORE CONNECTION BOX 400A | Q36: 3 | R36: 4161 | S36: AIR TREATMENT / CENTR. TRAIT. AIR | T36: 10P0.7,226612013P19-10P0.7,1060P013X26N,1060P013X25N,1060P013X19N,1060P013X22N,1060S013X03N,1060S014X02N,1060S012X02N,1060S012X16N,216512012S11,216523012S11,3163S012X06N,3163S012X04N,416134011S11,4161S011X07N | V36: NOT LOCAL CABLE | W36: WK39/2024 NEW CABLE | X36: 10P0.7 | Y36: 4161S011X07N
A37: 105 | B37: 105W0004 | C37: 1 | D37: 1 | G37: C 3X95 | H37: S1 | I37: 28.44 | J37: =ROUNDUP(I37,0) -> 29 | K37: (+10P0.7) | L37: 10P0.7 MAIN SWITCHBOARD 400VAC CONSUMERS | M37: 2266 | N37: SWITCHBOARD ROOM / LOCAL TABLEAUX | O37: (+10SC2) | P37: 10SC2 SHORE CONNECTION BOX 400A | Q37: 3 | R37: 4161 | S37: AIR TREATMENT / CENTR. TRAIT. AIR | T37: 10P0.7,226612013P19-10P0.7,1060P013X26N,1060P013X25N,1060P013X19N,1060P013X22N,1060S013X03N,1060S014X02N,1060S012X02N,1060S012X16N,216512012S11,216523012S11,3163S012X06N,3163S012X04N,416134011S11,4161S011X07N | V37: NOT LOCAL CABLE | W37: WK39/2024 NEW CABLE | X37: 10P0.7 | Y37: 4161S011X07N
A38: 122 | B38: 122W0001 | C38: 1 | D38: 1 | G38: C 3X25 | H38: S1 | I38: 8.05 | J38: =ROUNDUP(I38,0) -> 9 | K38: (+10P0.1) | L38: 10P0.1 MAIN SWITCHBOARD 400VAC CONSUMERS | M38: 2266 | N38: SWITCHBOARD ROOM / LOCAL TABLEAUX | O38: (=122++2266+-11T1) | P38: MAIN TRANSFORMER 1 | Q38: 1.5 | R38: 2266 | S38: SWITCHBOARD ROOM / LOCAL TABLEAUX | T38: 10P0.1,2266P012P07N,2266P011P02N | V38: LOCAL | W38: WK39/2024 NEW CABLE | X38: 10P0.1 | Y38: 2266P011P02N
A39: 122 | B39: 122W0003 | C39: 1 | G39: C 3X25 | H39: S1 | I39: 15.41 | J39: =ROUNDUP(I39,0) -> 16 | K39: (+10P0.7) | L39: 10P0.7 MAIN SWITCHBOARD 400VAC CONSUMERS | M39: 2266 | N39: SWITCHBOARD ROOM / LOCAL TABLEAUX | O39: (=122++2266+-11T2) | P39: MAIN TRANSFORMER 2 | Q39: 2.5 | R39: 2266 | S39: SWITCHBOARD ROOM / LOCAL TABLEAUX | T39: 10P0.7,2266P014P10N,2266P012P15N,2266P012P07N,2266P012P10N,2266P011P01N | V39: LOCAL | W39: WK39/2024 NEW CABLE | X39: 10P0.7 | Y39: 2266P011P01N
A40: 122 | B40: 122W0004 | C40: 1 | G40: C 3X25 | H40: S1 | I40: 53.46 | J40: =ROUNDUP(I40,0) -> 54 | K40: (+10P0.1) | L40: 10P0.1 MAIN SWITCHBOARD 400VAC CONSUMERS | M40: 2266 | N40: SWITCHBOARD ROOM / LOCAL TABLEAUX | O40: (+11P1) | P40: 11P1 400V/230V POWER DISTRIBUTION PANEL NO.1 - GALLEY & PANTRY SPACE | Q40: 3 | R40: 4040 | S40: ELECTRICAL ROOM / LOCAL ELECTRIQUE | T40: 10P0.1,226612013P17-10P0.1,1060P013X27N,1060P013X19N,1060P013X22N,1060S013X03N,1060S014X02N,1060S012X02N,1060S012X16N,216512012S11,216523012S11,3163S012X06N,3163S012X04N,3163S014X02N,316333015S11,3040S017X03N,3040S021X02N,3040S023X01N,3040S026X08N,304034028S11,4040S028X08N | V40: NOT LOCAL CABLE | W40: WK39/2024 NEW CABLE | X40: 10P0.1 | Y40: 4040S028X08N
...

Sheet nautics
A1: System | B1: Cable ID | C1: Cut | D1: Pulled | E1: Connection | F1: CWC- Megger | G1: Cable Type | H1: Segregation | I1: Design Length(m) | J1: Cable Cutting Length | K1: From Device | L1: From Device Description | M1: From Device Area | N1: From Device Area Description | O1: To Device | P1: To Device Description | Q1: To Device Area | R1: To Device Area Description | S1: Cable Route | T1: Local/Not Local Cables | U1: WK/REV.REASON | V1: From Node | W1: To Node
A2: 101.1 | B2: 101.1W0008 | C2: 1 | D2: 1 | G2: CAT7_S/FTP | H2: S2 | I2: 19.5 | J2: =ROUNDUP(I2,0) -> 20 | K2: (+40DE) | L2: 40DE SWITCHBOARD ROOM CONSOLE | M2: 2266 | N2: SWITCHBOARD ROOM / LOCAL TABLEAUX | O2: (=101.1++1060+-101.1U01) | P2: DIESEL GENERATOR FORE PANEL | Q2: 1060 | R2: ENGINE ROOM / SALLE DES MACHINES | S2: 40DE,106012012P11-40DE,1060P012X21N,1060P013X27N,1060P013X19N,1060P014X07N,1060P014X05N,1060P012X01N | T2: NOT LOCAL CABLE | U2: WK39/2024 NEW CABLE | V2: 40DE | W2: 1060P012X01N
B3: 101.1W0013 | C3: 1 | D3: 1 | G3: C+SH 12X1.5 | H3: S1 | I3: 25.17 | J3: =ROUNDUP(I3,0) -> 26 | K3: (=101.1++1060+-101.1U01) | L3: DIESEL GENERATOR FORE PANEL | M3: 1060 | N3: ENGINE ROOM / SALLE DES MACHINES | O3: (=101.1++1060+-101.1U02) | P3: SCR PANEL DIESEL GENERATOR FORE 10610E03 | Q3: 1060 | R3: ENGINE ROOM / SALLE DES MACHINES | S3: 1060P012X01N,1060P014X05N,1060P014X07N,1060P013X19N,1060P013X22N,1060S013X03N,1060S014X02N,1060S012X02N,1060S012X16N,1060S012X14N,1060S012X13N | T3: LOCAL | U3: WK39/2024 NEW CABLE | V3: 1060P012X01N | W3: 1060S012X13N
B4: 101.1W0014 | C4: 1 | D4: 1 | G4: TC+SH 1X2X0.75 | H4: S2 | I4: 25.17 | J4: =ROUNDUP(I4,0) -> 26 | K4: (=101.1++1060+-101.1U01) | L4: DIESEL GENERATOR FORE PANEL | M4: 1060 | N4: ENGINE ROOM / SALLE DES MACHINES | O4: (=101.1++1060+-101.1U02) | P4: SCR PANEL DIESEL GENERATOR FORE 10610E03 | Q4: 1060 | R4: ENGINE ROOM / SALLE DES MACHINES | S4: 1060P012X01N,1060P014X05N,1060P014X07N,1060P013X19N,1060P013X22N,1060S013X03N,1060S014X02N,1060S012X02N,1060S012X16N,1060S012X14N,1060S012X13N | T4: LOCAL | U4: WK39/2024 NEW CABLE | V4: 1060P012X01N | W4: 1060S012X13N
B5: 101.1W0017 | G5: ORIGINAL CABLE | H5: S2 | I5: 12.69 | J5: =ROUNDUP(I5,0) -> 13 | K5: (=101.1++1060+-101.1U03) | L5: EXAUST DIESEL GENERATOR FORE | M5: 1060 | N5: ENGINE ROOM / SALLE DES MACHINES | O5: (=101.1++1060+-101.1U02) | P5: SCR PANEL DIESEL GENERATOR FORE 10610E03 | Q5: 1060 | R5: ENGINE ROOM / SALLE DES MACHINES | S5: 1060S009X02N,1060S012X16N,1060S012X14N,1060S012X13N | T5: LOCAL | U5: WK39/2024 NEW CABLE | V5: 1060S009X02N | W5: 1060S012X13N
B6: 101.1W0018 | G6: ORIGINAL CABLE | H6: S2 | I6: 12.69 | J6: =ROUNDUP(I6,0) -> 13 | K6: (=101.1++1060+-101.1U03) | L6: EXAUST DIESEL GENERATOR FORE | M6: 1060 | N6: ENGINE ROOM / SALLE DES MACHINES | O6: (=101.1++1060+-101.1U02) | P6: SCR PANEL DIESEL GENERATOR FORE 10610E03 | Q6: 1060 | R6: ENGINE ROOM / SALLE DES MACHINES | S6: 1060S009X02N,1060S012X16N,1060S012X14N,1060S012X13N | T6: LOCAL | U6: WK39/2024 NEW CABLE | V6: 1060S009X02N | W6: 1060S012X13N
B7: 101.1W0019 | G7: ORIGINAL CABLE | H7: S2 | I7: 12.69 | J7: =ROUNDUP(I7,0) -> 13 | K7: (=101.1++1060+-101.1U03) | L7: EXAUST DIESEL GENERATOR FORE | M7: 1060 | N7: ENGINE ROOM / SALLE DES MACHINES | O7: (=101.1++1060+-101.1U02) | P7: SCR PANEL DIESEL GENERATOR FORE 10610E03 | Q7: 1060 | R7: ENGINE ROOM / SALLE DES MACHINES | S7: 1060S009X02N,1060S012X16N,1060S012X14N,1060S012X13N | T7: LOCAL | U7: WK39/2024 NEW CABLE | V7: 1060S009X02N | W7: 1060S012X13N
B8: 101.1W0020 | G8: ORIGINAL CABLE | H8: S2 | I8: 16.77 | J8: =ROUNDUP(I8,0) -> 17 | K8: (=101.1++1060+-101.1U04) | L8: DEF TANK DIESEL GENERATOR FORE 11210E03 | M8: 1060 | N8: ENGINE ROOM / SALLE DES MACHINES | O8: (=101.1++1060+-101.1U02) | P8: SCR PANEL DIESEL GENERATOR FORE 10610E03 | Q8: 1060 | R8: ENGINE ROOM / SALLE DES MACHINES | S8: 1060S009X02N,1060S012X16N,1060S012X14N,1060S012X13N | T8: LOCAL | U8: WK39/2024 NEW CABLE | V8: 1060S009X02N | W8: 1060S012X13N
B9: 101.1W0021 | G9: ORIGINAL CABLE | H9: S2 | I9: 15.19 | J9: =ROUNDUP(I9,0) -> 16 | K9: (=101.1++1060+-101.1U05) | L9: DEF PUMP DIESEL GENERATOR FORE 11210P03 | M9: 1060 | N9: ENGINE ROOM / SALLE DES MACHINES | O9: (=101.1++1060+-101.1U02) | P9: SCR PANEL DIESEL GENERATOR FORE 10610E03 | Q9: 1060 | R9: ENGINE ROOM / SALLE DES MACHINES | S9: 1060S012X12N,1060S012X11N,1060S012X02N,1060S012X16N,1060S012X14N,1060S012X13N | T9: LOCAL | U9: WK39/2024 NEW CABLE | V9: 1060S012X12N | W9: 1060S012X13N
B10: 101.1W0022 | G10: ORIGINAL CABLE | H10: S2 | I10: 14.66 | J10: =ROUNDUP(I10,0) -> 15 | K10: (=101.1++1060+-101.1U06) | L10: DOSING UNIT DIESEL GENERATOR FORE 11210E07 | M10: 1060 | N10: ENGINE ROOM / SALLE DES MACHINES | O10: (=101.1++1060+-101.1U02) | P10: SCR PANEL DIESEL GENERATOR FORE 10610E03 | Q10: 1060 | R10: ENGINE ROOM / SALLE DES MACHINES | S10: 1060P007X01N,1060S009X03N,1060S009X02N,1060S012X16N,1060S012X14N,1060S012X13N | T10: LOCAL | U10: WK39/2024 NEW CABLE | V10: 1060P007X01N | W10: 1060S012X13N
B11: 101.1W0023 | C11: 1 | D11: 1 | E11: 1 | G11: TC+SH 7X2X0.75 | H11: S2 | I11: 17.81 | J11: =ROUNDUP(I11,0) -> 18 | K11: (+10P0.2) | L11: 10P0.2 MAIN SWITCHBOARD DIESEL GENERATOR FWD | M11: 2266 | N11: SWITCHBOARD ROOM / LOCAL TABLEAUX | O11: (=101.1++1060+-101.1U01) | P11: DIESEL GENERATOR FORE PANEL | Q11: 1060 | R11: ENGINE ROOM / SALLE DES MACHINES | S11: 10P0.2,226612013P15-10P0.2,1060P013X27N,1060P013X19N,1060P014X07N,1060P014X05N,1060P012X01N | T11: NOT LOCAL CABLE | U11: WK39/2024 NEW CABLE | V11: 10P0.2 | W11: 1060P012X01N
B12: 101.1W0024 | C12: 1 | D12: 1 | E12: 1 | G12: TC+SH 2X2X0.75 | H12: S2 | I12: 17.81 | J12: =ROUNDUP(I12,0) -> 18 | K12: (+10P0.2) | L12: 10P0.2 MAIN SWITCHBOARD DIESEL GENERATOR FWD | M12: 2266 | N12: SWITCHBOARD ROOM / LOCAL TABLEAUX | O12: (=101.1++1060+-101.1U01) | P12: DIESEL GENERATOR FORE PANEL | Q12: 1060 | R12: ENGINE ROOM / SALLE DES MACHINES | S12: 10P0.2,226612013P15-10P0.2,1060P013X27N,1060P013X19N,1060P014X07N,1060P014X05N,1060P012X01N | T12: NOT LOCAL CABLE | U12: WK39/2024 NEW CABLE | V12: 10P0.2 | W12: 1060P012X01N
B13: 101.1W0025 | G13: ORIGINAL CABLE | H13: S2 | I13: 12.69 | J13: =ROUNDUP(I13,0) -> 13 | K13: (=101.1++1060+-101.1U03) | L13: EXAUST DIESEL GENERATOR FORE | M13: 1060 | N13: ENGINE ROOM / SALLE DES MACHINES | O13: (=101.1++1060+-101.1U02) | P13: SCR PANEL DIESEL GENERATOR FORE 10610E03 | Q13: 1060 | R13: ENGINE ROOM / SALLE DES MACHINES | S13: 1060S009X02N,1060S012X16N,1060S012X14N,1060S012X13N | T13: LOCAL | U13: WK39/2024 NEW CABLE | V13: 1060S009X02N | W13: 1060S012X13N
B14: 101.1W0026 | G14: ORIGINAL CABLE | H14: S2 | I14: 12.69 | J14: =ROUNDUP(I14,0) -> 13 | K14: (=101.1++1060+-101.1U03) | L14: EXAUST DIESEL GENERATOR FORE | M14: 1060 | N14: ENGINE ROOM / SALLE DES MACHINES | O14: (=101.1++1060+-101.1U02) | P14: SCR PANEL DIESEL GENERATOR FORE 10610E03 | Q14: 1060 | R14: ENGINE ROOM / SALLE DES MACHINES | S14: 1060S009X02N,1060S012X16N,1060S012X14N,1060S012X13N | T14: LOCAL | U14: WK39/2024 NEW CABLE | V14: 1060S009X02N | W14: 1060S012X13N
B15: 101.1W0027 | G15: ORIGINAL CABLE | H15: S2 | I15: 15.17 | J15: =ROUNDUP(I15,0) -> 16 | K15: (=101.1++1060+-101.1U08) | L15: FR UNIT SB | M15: 1060 | N15: ENGINE ROOM / SALLE DES MACHINES | O15: (=101.1++1060+-101.1U02) | P15: SCR PANEL DIESEL GENERATOR FORE 10610E03 | Q15: 1060 | R15: ENGINE ROOM / SALLE DES MACHINES | S15: 1060P007X01N,1060S009X03N,1060S009X02N,1060S012X16N,1060S012X14N,1060S012X13N | T15: LOCAL | U15: WK39/2024 NEW CABLE | V15: 1060P007X01N | W15: 1060S012X13N
B16: 101.1W0030 | C16: 1 | D16: 1 | G16: BUS 2X2X0.9 CAN | H16: S2 | I16: 58.51 | J16: =ROUNDUP(I16,0) -> 59 | K16: (+42DF.7) | L16: 42DF.7 CENTRAL CONSOLE | M16: 4032 | N16: WHEELHOUSE / TIMONERIE | O16: (=101.1++1060+-101.1U01) | P16: DIESEL GENERATOR FORE PANEL | Q16: 1060 | R16: ENGINE ROOM / SALLE DES MACHINES | S16: 4032P032X13N,4032S031X06N,304033030P11,3040P029X07N,3040P023X04N,3040P019X04N,3040P018X11N,3040P017X04N,3040P017X09N,204023018P11,2040P018X01N,2040P018X22N,226622015P11,226612014P11,1060P014X07N,1060P014X05N,1060P012X01N | T16: NOT LOCAL CABLE | U16: WK03/2025/UPDATE CABLE TYPE R1.01 | V16: 4032P032X13N | W16: 1060P012X01N
A17: 101.2 | B17: 101.2W0008 | C17: 1 | D17: 1 | G17: CAT7_S/FTP | H17: S2 | I17: 14.08 | J17: =ROUNDUP(I17,0) -> 15 | K17: (+40DE) | L17: 40DE SWITCHBOARD ROOM CONSOLE | M17: 2266 | N17: SWITCHBOARD ROOM / LOCAL TABLEAUX | O17: (=101.2++1060+-101.2U01) | P17: DIESEL GENERATOR AFT PANEL | Q17: 1060 | R17: ENGINE ROOM / SALLE DES MACHINES | S17: 40DE,106012012P11-40DE,1060P012X18N,1060P009X04N,1060P009X05N,1060S009X03N | T17: NOT LOCAL CABLE | U17: WK39/2024 NEW CABLE | V17: 40DE | W17: 1060S009X03N
B18: 101.2W0013 | C18: 1 | D18: 1 | G18: C+SH 12X1.5 | H18: S1 | I18: 14.79 | J18: =ROUNDUP(I18,0) -> 15 | K18: (=101.2++1060+-101.2U01) | L18: DIESEL GENERATOR AFT PANEL | M18: 1060 | N18: ENGINE ROOM / SALLE DES MACHINES | O18: (=101.2++1060+-101.2U02) | P18: SCR PANEL DIESEL GENERATOR AFT 10610E04 | Q18: 1060 | R18: ENGINE ROOM / SALLE DES MACHINES | S18: OFF ROUTE | T18: LOCAL | U18: WK10/2025/UPDATE CABLE LENGHT-PVN COMM R1.05 | V18: OFF ROUTE | W18: OFF ROUTE
B19: 101.2W0014 | C19: 1 | D19: 1 | G19: TC+SH 1X2X0.75 | H19: S2 | I19: 14.79 | J19: =ROUNDUP(I19,0) -> 15 | K19: (=101.2++1060+-101.2U01) | L19: DIESEL GENERATOR AFT PANEL | M19: 1060 | N19: ENGINE ROOM / SALLE DES MACHINES | O19: (=101.2++1060+-101.2U02) | P19: SCR PANEL DIESEL GENERATOR AFT 10610E04 | Q19: 1060 | R19: ENGINE ROOM / SALLE DES MACHINES | S19: OFF ROUTE | T19: LOCAL | U19: WK10/2025/UPDATE CABLE LENGHT-PVN COMM R1.05 | V19: OFF ROUTE | W19: OFF ROUTE
B20: 101.2W0017 | G20: ORIGINAL CABLE | H20: S2 | I20: 9.69 | J20: =ROUNDUP(I20,0) -> 10 | K20: (=101.2++1060+-101.2U03) | L20: EXAUST DIESEL GENERATOR AFT | M20: 1060 | N20: ENGINE ROOM / SALLE DES MACHINES | O20: (=101.2++1060+-101.2U02) | P20: SCR PANEL DIESEL GENERATOR AFT 10610E04 | Q20: 1060 | R20: ENGINE ROOM / SALLE DES MACHINES | S20: 1060P009X01N,1060P009X03N | T20: LOCAL | U20: WK39/2024 NEW CABLE | V20: 1060P009X01N | W20: 1060P009X03N
B21: 101.2W0018 | G21: ORIGINAL CABLE | H21: S2 | I21: 9.69 | J21: =ROUNDUP(I21,0) -> 10 | K21: (=101.2++1060+-101.2U03) | L21: EXAUST DIESEL GENERATOR AFT | M21: 1060 | N21: ENGINE ROOM / SALLE DES MACHINES | O21: (=101.2++1060+-101.2U02) | P21: SCR PANEL DIESEL GENERATOR AFT 10610E04 | Q21: 1060 | R21: ENGINE ROOM / SALLE DES MACHINES | S21: 1060P009X01N,1060P009X03N | T21: LOCAL | U21: WK39/2024 NEW CABLE | V21: 1060P009X01N | W21: 1060P009X03N
B22: 101.2W0019 | G22: ORIGINAL CABLE | H22: S2 | I22: 9.69 | J22: =ROUNDUP(I22,0) -> 10 | K22: (=101.2++1060+-101.2U03) | L22: EXAUST DIESEL GENERATOR AFT | M22: 1060 | N22: ENGINE ROOM / SALLE DES MACHINES | O22: (=101.2++1060+-101.2U02) | P22: SCR PANEL DIESEL GENERATOR AFT 10610E04 | Q22: 1060 | R22: ENGINE ROOM / SALLE DES MACHINES | S22: 1060P009X01N,1060P009X03N | T22: LOCAL | U22: WK39/2024 NEW CABLE | V22: 1060P009X01N | W22: 1060P009X03N
B23: 101.2W0020 | G23: ORIGINAL CABLE | H23: S2 | I23: 13.49 | J23: =ROUNDUP(I23,0) -> 14 | K23: (=101.2++1060+-101.2U04) | L23: DEF TANK DIESEL GENERATOR AFT 11210E04 | M23: 1060 | N23: ENGINE ROOM / SALLE DES MACHINES | O23: (=101.2++1060+-101.2U02) | P23: SCR PANEL DIESEL GENERATOR AFT 10610E04 | Q23: 1060 | R23: ENGINE ROOM / SALLE DES MACHINES | S23: 1060P009X04N,1060P009X03N | T23: LOCAL | U23: WK39/2024 NEW CABLE | V23: 1060P009X04N | W23: 1060P009X03N
B24: 101.2W0021 | G24: ORIGINAL CABLE | H24: S2 | I24: 16.74 | J24: =ROUNDUP(I24,0) -> 17 | K24: (=101.2++1060+-101.2U05) | L24: DEF PUMP DIESEL GENERATOR AFT 11210P04 | M24: 1060 | N24: ENGINE ROOM / SALLE DES MACHINES | O24: (=101.2++1060+-101.2U02) | P24: SCR PANEL DIESEL GENERATOR AFT 10610E04 | Q24: 1060 | R24: ENGINE ROOM / SALLE DES MACHINES | S24: 1060P011X35N,1060P011X37N,1060P012X21N,1060P012X18N,1060P009X04N,1060P009X03N | T24: LOCAL | U24: WK39/2024 NEW CABLE | V24: 1060P011X35N | W24: 1060P009X03N
B25: 101.2W0022 | G25: ORIGINAL CABLE | H25: S2 | I25: 8.62 | J25: =ROUNDUP(I25,0) -> 9 | K25: (=101.2++1060+-101.2U06) | L25: DOSING UNIT DIESEL GENERATOR AFT 11210E08 | M25: 1060 | N25: ENGINE ROOM / SALLE DES MACHINES | O25: (=101.2++1060+-101.2U02) | P25: SCR PANEL DIESEL GENERATOR AFT 10610E04 | Q25: 1060 | R25: ENGINE ROOM / SALLE DES MACHINES | S25: 1060P008X01N,1060P009X05N,1060P009X03N | T25: LOCAL | U25: WK39/2024 NEW CABLE | V25: 1060P008X01N | W25: 1060P009X03N
B26: 101.2W0023 | C26: 1 | D26: 1 | E26: 1 | G26: TC+SH 7X2X0.75 | H26: S2 | I26: 16.29 | J26: =ROUNDUP(I26,0) -> 17 | K26: (+10P0.6) | L26: 10P0.6 MAIN SWITCHBOARD DIESEL GENERATOR AFT | M26: 2266 | N26: SWITCHBOARD ROOM / LOCAL TABLEAUX | O26: (=101.2++1060+-101.2U01) | P26: DIESEL GENERATOR AFT PANEL | Q26: 1060 | R26: ENGINE ROOM / SALLE DES MACHINES | S26: 10P0.6,226612013P14-10P0.6,1060P013X25N,1060P013X19N,1060P013X27N,1060P012X21N,1060P012X18N,1060P009X04N,1060P009X05N,1060S009X03N | T26: NOT LOCAL CABLE | U26: WK39/2024 NEW CABLE | V26: 10P0.6 | W26: 1060S009X03N
B27: 101.2W0024 | C27: 1 | D27: 1 | E27: 1 | G27: TC+SH 2X2X0.75 | H27: S2 | I27: 16.29 | J27: =ROUNDUP(I27,0) -> 17 | K27: (+10P0.6) | L27: 10P0.6 MAIN SWITCHBOARD DIESEL GENERATOR AFT | M27: 2266 | N27: SWITCHBOARD ROOM / LOCAL TABLEAUX | O27: (=101.2++1060+-101.2U01) | P27: DIESEL GENERATOR AFT PANEL | Q27: 1060 | R27: ENGINE ROOM / SALLE DES MACHINES | S27: 10P0.6,226612013P14-10P0.6,1060P013X25N,1060P013X19N,1060P013X27N,1060P012X21N,1060P012X18N,1060P009X04N,1060P009X05N,1060S009X03N | T27: NOT LOCAL CABLE | U27: WK39/2024 NEW CABLE | V27: 10P0.6 | W27: 1060S009X03N
B28: 101.2W0025 | G28: ORIGINAL CABLE | H28: S2 | I28: 9.69 | J28: =ROUNDUP(I28,0) -> 10 | K28: (=101.2++1060+-101.2U03) | L28: EXAUST DIESEL GENERATOR AFT | M28: 1060 | N28: ENGINE ROOM / SALLE DES MACHINES | O28: (=101.2++1060+-101.2U02) | P28: SCR PANEL DIESEL GENERATOR AFT 10610E04 | Q28: 1060 | R28: ENGINE ROOM / SALLE DES MACHINES | S28: 1060P009X01N,1060P009X03N | T28: LOCAL | U28: WK39/2024 NEW CABLE | V28: 1060P009X01N | W28: 1060P009X03N
B29: 101.2W0026 | G29: ORIGINAL CABLE | H29: S2 | I29: 9.69 | J29: =ROUNDUP(I29,0) -> 10 | K29: (=101.2++1060+-101.2U03) | L29: EXAUST DIESEL GENERATOR AFT | M29: 1060 | N29: ENGINE ROOM / SALLE DES MACHINES | O29: (=101.2++1060+-101.2U02) | P29: SCR PANEL DIESEL GENERATOR AFT 10610E04 | Q29: 1060 | R29: ENGINE ROOM / SALLE DES MACHINES | S29: 1060P009X01N,1060P009X03N | T29: LOCAL | U29: WK39/2024 NEW CABLE | V29: 1060P009X01N | W29: 1060P009X03N
B30: 101.2W0027 | G30: ORIGINAL CABLE | H30: S2 | I30: 11.11 | J30: =ROUNDUP(I30,0) -> 12 | K30: (=101.2++1060+-101.2U08) | L30: FR UNIT PS | M30: 1060 | N30: ENGINE ROOM / SALLE DES MACHINES | O30: (=101.2++1060+-101.2U02) | P30: SCR PANEL DIESEL GENERATOR AFT 10610E04 | Q30: 1060 | R30: ENGINE ROOM / SALLE DES MACHINES | S30: 1060P007X01N,1060S009X03N,1060P009X05N,1060P009X03N | T30: LOCAL | U30: WK39/2024 NEW CABLE | V30: 1060P007X01N | W30: 1060P009X03N
B31: 101.2W0030 | C31: 1 | D31: 1 | G31: BUS 2X2X0.9 CAN | H31: S2 | I31: 57.43 | J31: =ROUNDUP(I31,0) -> 58 | K31: (+42DF.7) | L31: 42DF.7 CENTRAL CONSOLE | M31: 4032 | N31: WHEELHOUSE / TIMONERIE | O31: (=101.2++1060+-101.2U01) | P31: DIESEL GENERATOR AFT PANEL | Q31: 1060 | R31: ENGINE ROOM / SALLE DES MACHINES | S31: 4032P032X13N,4032S031X06N,4032S031X05N,4032S031X03N,304033030S11,3040S027X02N,3040S027X03N,3040S023X01N,3040S021X02N,3040S017X03N,316333015S11,3163S014X02N,3163S012X04N,3163S012X06N,216523012S11,216512012S11,1060S012X16N,1060S009X02N,1060S009X03N | T31: NOT LOCAL CABLE | U31: WK03/2025/UPDATE CABLE TYPE R1.01 | V31: 4032P032X13N | W31: 1060S009X03N
A32: 102 | B32: 102W0001 | C32: 1 | D32: 1 | E32: 2 | G32: TC+SH 10X2X0.75 | H32: S2 | I32: 8.71 | J32: =ROUNDUP(I32,0) -> 9 | K32: (+12EP0.1) | L32: 12EP0.1 EMERGENCY SWITCHBOARD EDG 52KW / MSB TRANSFER LINE / CONSUMERS 3X400V 50HZ | M32: 4262 | N32: EMG. GENSET / GROUPE DE SECOURS | O32: (=102++4262+-102U01) | P32: EMERGENCY GENERATOR PANEL | Q32: 4262 | R32: EMG. GENSET / GROUPE DE SECOURS | S32: 12EP0.1,4262P013X06N | T32: LOCAL | U32: WK39/2024 NEW CABLE | V32: 12EP0.1 | W32: 4262P013X06N
B33: 102W0002 | C33: 1 | D33: 1 | E33: 2 | G33: TC+SH 7X2X0.75 | H33: S2 | I33: 8.71 | J33: =ROUNDUP(I33,0) -> 9 | K33: (+12EP0.1) | L33: 12EP0.1 EMERGENCY SWITCHBOARD EDG 52KW / MSB TRANSFER LINE / CONSUMERS 3X400V 50HZ | M33: 4262 | N33: EMG. GENSET / GROUPE DE SECOURS | O33: (=102++4262+-102U01) | P33: EMERGENCY GENERATOR PANEL | Q33: 4262 | R33: EMG. GENSET / GROUPE DE SECOURS | S33: 12EP0.1,4262P013X06N | T33: LOCAL | U33: WK39/2024 NEW CABLE | V33: 12EP0.1 | W33: 4262P013X06N
B34: 102W0012 | C34: 1 | D34: 1 | G34: CAT7_S/FTP | H34: S2 | I34: 44.69 | J34: =ROUNDUP(I34,0) -> 45 | K34: (+42DF.7) | L34: 42DF.7 CENTRAL CONSOLE | M34: 4032 | N34: WHEELHOUSE / TIMONERIE | O34: (=102++4262+-102U01) | P34: EMERGENCY GENERATOR PANEL | Q34: 4262 | R34: EMG. GENSET / GROUPE DE SECOURS | S34: 4032P032X13N,4032S031X06N,304033030P11,3040P027X05N,3040P024X02N,3040P020X02N,3040P019X04N,304034019P11,4256P019X04N,4256P019X08N,4258P017X01N,425844015P11,4262P015X03N,4262P013X06N | T34: NOT LOCAL CABLE | U34: WK39/2024 NEW CABLE | V34: 4032P032X13N | W34: 4262P013X06N
A35: 105 | B35: 105W0007 | C35: 1 | D35: 1 | E35: 1 | G35: TC+SH 4X2X0.75 | H35: S2 | I35: 13.15 | J35: =ROUNDUP(I35,0) -> 14 | K35: (+10P0.1) | L35: 10P0.1 MAIN SWITCHBOARD 400VAC CONSUMERS | M35: 2266 | N35: SWITCHBOARD ROOM / LOCAL TABLEAUX | O35: (+40DE) | P35: 40DE SWITCHBOARD ROOM CONSOLE | Q35: 2266 | R35: SWITCHBOARD ROOM / LOCAL TABLEAUX | S35: 10P0.1,2266P012P07N,40DE | T35: LOCAL | U35: WK39/2024 NEW CABLE | V35: 10P0.1 | W35: 40DE
B36: 105W0008 | C36: 1 | D36: 1 | E36: 1 | G36: TC+SH 4X2X0.75 | H36: S2 | I36: 15.63 | J36: =ROUNDUP(I36,0) -> 16 | K36: (+10P0.7) | L36: 10P0.7 MAIN SWITCHBOARD 400VAC CONSUMERS | M36: 2266 | N36: SWITCHBOARD ROOM / LOCAL TABLEAUX | O36: (+40DE) | P36: 40DE SWITCHBOARD ROOM CONSOLE | Q36: 2266 | R36: SWITCHBOARD ROOM / LOCAL TABLEAUX | S36: 10P0.7,226612013P19-10P0.7,1060P013X26N,1060P013X25N,1060P013X19N,1060P013X27N,1060P012X21N,106012012P12-40DE,40DE | T36: LOCAL | U36: WK39/2024 NEW CABLE | V36: 10P0.7 | W36: 40DE
A37: 122 | B37: 122W0011 | C37: 1 | D37: 1 | E37: 1 | G37: TC+SH 14X2X0.75 | H37: S2 | I37: 13.15 | J37: =ROUNDUP(I37,0) -> 14 | K37: (+10P0.1) | L37: 10P0.1 MAIN SWITCHBOARD 400VAC CONSUMERS | M37: 2266 | N37: SWITCHBOARD ROOM / LOCAL TABLEAUX | O37: (+40DE) | P37: 40DE SWITCHBOARD ROOM CONSOLE | Q37: 2266 | R37: SWITCHBOARD ROOM / LOCAL TABLEAUX | S37: 10P0.1,2266P012P07N,40DE | T37: LOCAL | U37: WK39/2024 NEW CABLE | V37: 10P0.1 | W37: 40DE
B38: 122W0012 | C38: 1 | D38: 1 | E38: 1 | G38: TC+SH 14X2X0.75 | H38: S2 | I38: 13.15 | J38: =ROUNDUP(I38,0) -> 14 | K38: (+10P0.1) | L38: 10P0.1 MAIN SWITCHBOARD 400VAC CONSUMERS | M38: 2266 | N38: SWITCHBOARD ROOM / LOCAL TABLEAUX | O38: (+40DE) | P38: 40DE SWITCHBOARD ROOM CONSOLE | Q38: 2266 | R38: SWITCHBOARD ROOM / LOCAL TABLEAUX | S38: 10P0.1,2266P012P07N,40DE | T38: LOCAL | U38: WK39/2024 NEW CABLE | V38: 10P0.1 | W38: 40DE
B39: 122W0013 | C39: 1 | D39: 1 | E39: 1 | G39: TC+SH 10X2X0.75 | H39: S2 | I39: 15.63 | J39: =ROUNDUP(I39,0) -> 16 | K39: (+10P0.7) | L39: 10P0.7 MAIN SWITCHBOARD 400VAC CONSUMERS | M39: 2266 | N39: SWITCHBOARD ROOM / LOCAL TABLEAUX | O39: (+40DE) | P39: 40DE SWITCHBOARD ROOM CONSOLE | Q39: 2266 | R39: SWITCHBOARD ROOM / LOCAL TABLEAUX | S39: 10P0.7,226612013P19-10P0.7,1060P013X26N,1060P013X25N,1060P013X19N,1060P013X27N,1060P012X21N,106012012P12-40DE,40DE | T39: LOCAL | U39: WK39/2024 NEW CABLE | V39: 10P0.7 | W39: 40DE
B40: 122W0014 | C40: 1 | D40: 1 | E40: 1 | G40: TC+SH 10X2X0.75 | H40: S2 | I40: 15.63 | J40: =ROUNDUP(I40,0) -> 16 | K40: (+10P0.7) | L40: 10P0.7 MAIN SWITCHBOARD 400VAC CONSUMERS | M40: 2266 | N40: SWITCHBOARD ROOM / LOCAL TABLEAUX | O40: (+40DE) | P40: 40DE SWITCHBOARD ROOM CONSOLE | Q40: 2266 | R40: SWITCHBOARD ROOM / LOCAL TABLEAUX | S40: 10P0.7,226612013P19-10P0.7,1060P013X26N,1060P013X25N,1060P013X19N,1060P013X27N,1060P012X21N,106012012P12-40DE,40DE | T40: LOCAL | U40: WK39/2024 NEW CABLE | V40: 10P0.7 | W40: 40DE
...

Sheet st
A1: System | B1: Cable ID | C1: Cut | D1: Pulled | E1: Connection | F1: CWC- Megger | G1: Cable Type | H1: Segregation | I1: Design Length(m) | J1: Cable Cutting Length | K1: From Device | L1: From Device Description | M1: From Device Area | N1: From Device Area Description | O1: To Device | P1: To Device Description | Q1: To Device Area | R1: To Device Area Description | S1: Cable Route | T1: Local/Not Local Cables | U1: WK/REV.REASON | V1: From Node | W1: To Node
A2: 715 | B2: 715W0009 | C2: 1 | D2: 1 | G2: COAX RG214 | H2: S2 | I2: 29.99 | J2: =ROUNDUP(I2,0) -> 30 | K2: (+43DA) | L2: 43DA GMDSS STATION | M2: 4032 | N2: WHEELHOUSE / TIMONERIE | O2: (=715++5010+-715U13) | P2: SSAS IC-119 | Q2: 5010 | R2: TOP DECK / TOIT | S2: 4032P031X01N,4032S031X06N,4032S031X05N,404044030S11,404044028P12,4242P028X04N,5010P027X04G | T2: NOT LOCAL CABLE | U2: WK46/2025/UPDATE CABLE TYPE R1.12 | V2: 4032P031X01N | W2: 5010P027X04G
A3: 715 | B3: 715W0010 | G3: ORIGINAL CABLE | H3: S2 | I3: 5.1 | J3: =ROUNDUP(I3,0) -> 6 | K3: (+43DA) | L3: 43DA GMDSS STATION | M3: 4032 | N3: WHEELHOUSE / TIMONERIE | O3: (+43DA) | P3: 43DA GMDSS STATION | Q3: 4032 | R3: WHEELHOUSE / TIMONERIE | S3: OFF ROUTE | T3: LOCAL | U3: WK03/2025/NEW CABLE R1.01 | V3: OFF ROUTE | W3: OFF ROUTE
A4: 715 | B4: 715W0011 | C4: 1 | G4: TC+SH 4X2X0.75 | H4: S2 | I4: 5.1 | J4: =ROUNDUP(I4,0) -> 6 | K4: (+43DA) | L4: 43DA GMDSS STATION | M4: 4032 | N4: WHEELHOUSE / TIMONERIE | O4: (+43DA) | P4: 43DA GMDSS STATION | Q4: 4032 | R4: WHEELHOUSE / TIMONERIE | S4: OFF ROUTE | T4: LOCAL | U4: WK39/2024 NEW CABLE | V4: OFF ROUTE | W4: OFF ROUTE
A5: 715 | B5: 715W0012 | C5: 1 | D5: 1 | G5: TC+SH 4X2X0.75 | H5: S2 | I5: 59.7 | J5: =ROUNDUP(I5,0) -> 60 | K5: (+43DA) | L5: 43DA GMDSS STATION | M5: 4032 | N5: WHEELHOUSE / TIMONERIE | O5: (=715++3163+-715U17) | P5: SSAS BUTTON IC-307 NO 2 | Q5: 3163 | R5: CAPT CAB / CAB COMMANDANT | S5: 3163S013X02N,3163S014X02N,316333015S11,3040S017X03N,3040S021X02N,3040S023X01N,3040S026X08N,304034028S11,404044030S11,4032S031X05N,4032S031X06N,4032P031X01N | T5: NOT LOCAL CABLE | U5: WK03/2026/UPDATE CABLE TYPE R1.13 | V5: 4032P031X01N | W5: 3163S013X02N
A6: 721 | B6: 721W0001 | C6: 1 | D6: 1 | G6: C+SH 3X2.5 | H6: S1 | I6: 50.68 | J6: =ROUNDUP(I6,0) -> 51 | K6: (+10P0.8) | L6: 10P0.8 MAIN SWITCHBOARD 230VAC CONSUMERS | M6: 2266 | N6: SWITCHBOARD ROOM / LOCAL TABLEAUX | O6: (+43DA) | P6: 43DA GMDSS STATION | Q6: 4032 | R6: WHEELHOUSE / TIMONERIE | S6: 10P0.8,226612013P20-10P0.8,226612013P11,226623013P11,3264P012X08N,3264P012X04N,3264P015X01N,3264P015X05N,304033015P11,3040P018X06N,3040P020X03N,3040P020X02N,3040P024X02N,3040P027X05N,304033030P11,4032P031X01N | T6: NOT LOCAL CABLE | U6: WK39/2024 NEW CABLE | V6: 10P0.8 | W6: 4032P031X01N
A7: 721 | B7: 721W0002 | C7: 1 | D7: 1 | G7: C+SH 3X2.5 | H7: S1 | I7: 36.03 | J7: =ROUNDUP(I7,0) -> 37 | K7: (+12EP0.2) | L7: 12EP0.2 EMERGENCY SWITCHBOARD CONSUMERS 3X230V 50HZ | M7: 4262 | N7: EMG. GENSET / GROUPE DE SECOURS | O7: (+43DA) | P7: 43DA GMDSS STATION | Q7: 4032 | R7: WHEELHOUSE / TIMONERIE | S7: 12EP0.2,326434015P12,304033015P11,3040P018X06N,3040P020X03N,3040P020X02N,3040P024X02N,3040P027X05N,304033030P11,4032P031X01N | T7: NOT LOCAL CABLE | U7: WK39/2024 NEW CABLE | V7: 12EP0.2 | W7: 4032P031X01N
A8: 721 | B8: 721W0003 | C8: 1 | G8: C+SH 1X35 | H8: S1 | I8: 5.1 | J8: =ROUNDUP(I8,0) -> 6 | K8: (+43DA) | L8: 43DA GMDSS STATION | M8: 4032 | N8: WHEELHOUSE / TIMONERIE | O8: (+43DA) | P8: 43DA GMDSS STATION | Q8: 4032 | R8: WHEELHOUSE / TIMONERIE | S8: OFF ROUTE | T8: LOCAL | U8: WK39/2024 NEW CABLE | V8: OFF ROUTE | W8: OFF ROUTE
A9: 721 | B9: 721W0004 | C9: 1 | G9: C+SH 1X35 | H9: S1 | I9: 5.1 | J9: =ROUNDUP(I9,0) -> 6 | K9: (+43DA) | L9: 43DA GMDSS STATION | M9: 4032 | N9: WHEELHOUSE / TIMONERIE | O9: (+43DA) | P9: 43DA GMDSS STATION | Q9: 4032 | R9: WHEELHOUSE / TIMONERIE | S9: OFF ROUTE | T9: LOCAL | U9: WK39/2024 NEW CABLE | V9: OFF ROUTE | W9: OFF ROUTE
A10: 721 | B10: 721W0005 | C10: 1 | D10: 1 | G10: C+SH 1X35 | H10: S1 | I10: 19.41 | J10: =ROUNDUP(I10,0) -> 20 | K10: (+43DA) | L10: 43DA GMDSS STATION | M10: 4032 | N10: WHEELHOUSE / TIMONERIE | O10: (=721++5010+-721U03) | P10: GMDSS BATTERIES | Q10: 5010 | R10: TOP DECK / TOIT | S10: 4032P031X01N,4032S031X06N,4032S031X05N,4032S030X17N,4032P030X01N,5010P030X26G | T10: NOT LOCAL CABLE | U10: WK39/2024 NEW CABLE | V10: 4032P031X01N | W10: 5010P030X26G
A11: 721 | B11: 721W0006 | C11: 1 | D11: 1 | G11: C+SH 1X35 | H11: S1 | I11: 19.41 | J11: =ROUNDUP(I11,0) -> 20 | K11: (+43DA) | L11: 43DA GMDSS STATION | M11: 4032 | N11: WHEELHOUSE / TIMONERIE | O11: (=721++5010+-721U03) | P11: GMDSS BATTERIES | Q11: 5010 | R11: TOP DECK / TOIT | S11: 4032P031X01N,4032S031X06N,4032S031X05N,4032S030X17N,4032P030X01N,5010P030X31G | T11: NOT LOCAL CABLE | U11: WK39/2024 NEW CABLE | V11: 4032P031X01N | W11: 5010P030X31G
A12: 721 | B12: 721W0007 | C12: 1 | G12: TC+SH 4X2X0.75 | H12: S2 | I12: 5.1 | J12: =ROUNDUP(I12,0) -> 6 | K12: (+43DA) | L12: 43DA GMDSS STATION | M12: 4032 | N12: WHEELHOUSE / TIMONERIE | O12: (+43DA) | P12: 43DA GMDSS STATION | Q12: 4032 | R12: WHEELHOUSE / TIMONERIE | S12: OFF ROUTE | T12: LOCAL | U12: WK39/2024 NEW CABLE | V12: OFF ROUTE | W12: OFF ROUTE
A13: 721 | B13: 721W0008 | C13: 1 | G13: C+SH 2X2.5 | H13: S1 | I13: 5.1 | J13: =ROUNDUP(I13,0) -> 6 | K13: (+43DA) | L13: 43DA GMDSS STATION | M13: 4032 | N13: WHEELHOUSE / TIMONERIE | O13: (+43DA) | P13: 43DA GMDSS STATION | Q13: 4032 | R13: WHEELHOUSE / TIMONERIE | S13: OFF ROUTE | T13: LOCAL | U13: WK39/2024 NEW CABLE | V13: OFF ROUTE | W13: OFF ROUTE
A14: 721 | B14: 721W0009 | C14: 1 | G14: C+SH 2X2.5 | H14: S1 | I14: 5.1 | J14: =ROUNDUP(I14,0) -> 6 | K14: (+43DA) | L14: 43DA GMDSS STATION | M14: 4032 | N14: WHEELHOUSE / TIMONERIE | O14: (+43DA) | P14: 43DA GMDSS STATION | Q14: 4032 | R14: WHEELHOUSE / TIMONERIE | S14: OFF ROUTE | T14: LOCAL | U14: WK39/2024 NEW CABLE | V14: OFF ROUTE | W14: OFF ROUTE
A15: 721 | B15: 721W0010 | C15: 1 | G15: C+SH 2X2.5 | H15: S1 | I15: 5.1 | J15: =ROUNDUP(I15,0) -> 6 | K15: (+43DA) | L15: 43DA GMDSS STATION | M15: 4032 | N15: WHEELHOUSE / TIMONERIE | O15: (+43DA) | P15: 43DA GMDSS STATION | Q15: 4032 | R15: WHEELHOUSE / TIMONERIE | S15: OFF ROUTE | T15: LOCAL | U15: WK39/2024 NEW CABLE | V15: OFF ROUTE | W15: OFF ROUTE
A16: 721 | B16: 721W0011 | C16: 1 | G16: C+SH 2X2.5 | H16: S1 | I16: 5.1 | J16: =ROUNDUP(I16,0) -> 6 | K16: (+43DA) | L16: 43DA GMDSS STATION | M16: 4032 | N16: WHEELHOUSE / TIMONERIE | O16: (+43DA) | P16: 43DA GMDSS STATION | Q16: 4032 | R16: WHEELHOUSE / TIMONERIE | S16: OFF ROUTE | T16: LOCAL | U16: WK39/2024 NEW CABLE | V16: OFF ROUTE | W16: OFF ROUTE
A17: 721 | B17: 721W0012 | C17: 1 | D17: 1 | G17: C+SH 2X2.5 | H17: S1 | I17: 19.44 | J17: =ROUNDUP(I17,0) -> 20 | K17: (+42DF.6) | L17: 42DF.6 SB RIGHT | M17: 4032 | N17: WHEELHOUSE / TIMONERIE | O17: (+43DA) | P17: 43DA GMDSS STATION | Q17: 4032 | R17: WHEELHOUSE / TIMONERIE | S17: 4032S032X01N,4032S031X01N,4032S031X02N,4032S031X03N,4032S031X05N,4032S031X06N,4032P031X01N | T17: LOCAL | U17: WK03/2025/UPDATE CABLE TYPE R1.01 | V17: 4032S032X01N | W17: 4032P031X01N
A18: 721 | B18: 721W0013 | C18: 1 | G18: C+SH 2X2.5 | H18: S1 | I18: 5.1 | J18: =ROUNDUP(I18,0) -> 6 | K18: (+43DA) | L18: 43DA GMDSS STATION | M18: 4032 | N18: WHEELHOUSE / TIMONERIE | O18: (+43DA) | P18: 43DA GMDSS STATION | Q18: 4032 | R18: WHEELHOUSE / TIMONERIE | S18: OFF ROUTE | T18: LOCAL | U18: WK39/2024 NEW CABLE | V18: OFF ROUTE | W18: OFF ROUTE
A19: 721 | B19: 721W0014 | G19: ORIGINAL CABLE 2X | H19: S1 | I19: 5.1 | J19: =ROUNDUP(I19,0) -> 6 | K19: (+43DA) | L19: 43DA GMDSS STATION | M19: 4032 | N19: WHEELHOUSE / TIMONERIE | O19: (+43DA) | P19: 43DA GMDSS STATION | Q19: 4032 | R19: WHEELHOUSE / TIMONERIE | S19: OFF ROUTE | T19: LOCAL | U19: WK03/2025/NEW CABLE R1.01 | V19: OFF ROUTE | W19: OFF ROUTE
A20: 721 | B20: 721W0015 | C20: 1 | G20: C+SH 2X2.5 | H20: S1 | I20: 5.1 | J20: =ROUNDUP(I20,0) -> 6 | K20: (+43DA) | L20: 43DA GMDSS STATION | M20: 4032 | N20: WHEELHOUSE / TIMONERIE | O20: (+43DA) | P20: 43DA GMDSS STATION | Q20: 4032 | R20: WHEELHOUSE / TIMONERIE | S20: OFF ROUTE | T20: LOCAL | U20: WK03/2025/NEW CABLE R1.01 | V20: OFF ROUTE | W20: OFF ROUTE
A21: 721 | B21: 721W0016 | G21: ORIGINAL CABLE 2X | H21: S1 | I21: 5.1 | J21: =ROUNDUP(I21,0) -> 6 | K21: (+43DA) | L21: 43DA GMDSS STATION | M21: 4032 | N21: WHEELHOUSE / TIMONERIE | O21: (+43DA) | P21: 43DA GMDSS STATION | Q21: 4032 | R21: WHEELHOUSE / TIMONERIE | S21: OFF ROUTE | T21: LOCAL | U21: WK03/2025/NEW CABLE R1.01 | V21: OFF ROUTE | W21: OFF ROUTE
A22: 721 | B22: 721W0017 | G22: ORIGINAL CABLE 2X | H22: S1 | I22: 5.1 | J22: =ROUNDUP(I22,0) -> 6 | K22: (+43DA) | L22: 43DA GMDSS STATION | M22: 4032 | N22: WHEELHOUSE / TIMONERIE | O22: (+43DA) | P22: 43DA GMDSS STATION | Q22: 4032 | R22: WHEELHOUSE / TIMONERIE | S22: OFF ROUTE | T22: LOCAL | U22: WK03/2025/NEW CABLE R1.01 | V22: OFF ROUTE | W22: OFF ROUTE
A23: 721 | B23: 721W0018 | G23: ORIGINAL CABLE 2X | H23: S1 | I23: 5.1 | J23: =ROUNDUP(I23,0) -> 6 | K23: (+43DA) | L23: 43DA GMDSS STATION | M23: 4032 | N23: WHEELHOUSE / TIMONERIE | O23: (+43DA) | P23: 43DA GMDSS STATION | Q23: 4032 | R23: WHEELHOUSE / TIMONERIE | S23: OFF ROUTE | T23: LOCAL | U23: WK03/2025/NEW CABLE R1.01 | V23: OFF ROUTE | W23: OFF ROUTE
A24: 721 | B24: 721W0019 | G24: ORIGINAL CABLE 2X | H24: S1 | I24: 5.1 | J24: =ROUNDUP(I24,0) -> 6 | K24: (+43DA) | L24: 43DA GMDSS STATION | M24: 4032 | N24: WHEELHOUSE / TIMONERIE | O24: (+43DA) | P24: 43DA GMDSS STATION | Q24: 4032 | R24: WHEELHOUSE / TIMONERIE | S24: OFF ROUTE | T24: LOCAL | U24: WK03/2025/NEW CABLE R1.01 | V24: OFF ROUTE | W24: OFF ROUTE
A25: 721 | B25: 721W0020 | C25: 1 | G25: C+SH 2X1.5 | H25: S1 | I25: 9.69 | J25: =ROUNDUP(I25,0) -> 10 | K25: (+43DA) | L25: 43DA GMDSS STATION | M25: 4032 | N25: WHEELHOUSE / TIMONERIE | O25: (=721++4032+-721U13) | P25: EMERGENCY LIGHT | Q25: 4032 | R25: WHEELHOUSE / TIMONERIE | S25: OFF ROUTE | T25: LOCAL | U25: WK39/2024 NEW CABLE | V25: OFF ROUTE | W25: OFF ROUTE
A26: 721 | B26: 721W0021 | C26: 1 | G26: C+SH 2X2.5 | H26: S1 | I26: 5.1 | J26: =ROUNDUP(I26,0) -> 6 | K26: (+43DA) | L26: 43DA GMDSS STATION | M26: 4032 | N26: WHEELHOUSE / TIMONERIE | O26: (+43DA) | P26: 43DA GMDSS STATION | Q26: 4032 | R26: WHEELHOUSE / TIMONERIE | S26: OFF ROUTE | T26: LOCAL | U26: WK39/2024 NEW CABLE | V26: OFF ROUTE | W26: OFF ROUTE
A27: 721 | B27: 721W0022 | C27: 1 | D27: 1 | G27: C+SH 2X2.5 | H27: S1 | I27: 25.64 | J27: =ROUNDUP(I27,0) -> 26 | K27: (+43DA) | L27: 43DA GMDSS STATION | M27: 4032 | N27: WHEELHOUSE / TIMONERIE | O27: (+47CC) | P27: 47CC OVERHEAD CONSOLE | Q27: 4032 | R27: WHEELHOUSE / TIMONERIE | S27: 4032P031X01N,4032S031X06N,4032S031X05N,4032S030X17N,4032S030X19N,4032S030X11N,4032S032X06N,4032S032X09N | T27: LOCAL | U27: WK03/2025/UPDATE TARGET&CTYPE&CABLE LENGHT R1.01 | V27: 4032P031X01N | W27: 4032S032X09N
A28: 721 | B28: 721W0023 | C28: 1 | G28: C+SH 2X2.5 | H28: S1 | I28: 5.1 | J28: =ROUNDUP(I28,0) -> 6 | K28: (+43DA) | L28: 43DA GMDSS STATION | M28: 4032 | N28: WHEELHOUSE / TIMONERIE | O28: (+43DA) | P28: 43DA GMDSS STATION | Q28: 4032 | R28: WHEELHOUSE / TIMONERIE | S28: OFF ROUTE | T28: LOCAL | U28: WK03/2025/UPDATE CABLE TYPE R1.01 | V28: OFF ROUTE | W28: OFF ROUTE
A29: 721 | B29: 721W0024 | C29: 1 | D29: 1 | G29: C+SH 3X1.5 | H29: S1 | I29: 15.06 | J29: =ROUNDUP(I29,0) -> 16 | K29: (+16NA) | L29: "16NA" 230VAC NAUTICAL DISTRIBUTION PANEL | M29: 4032 | N29: WHEELHOUSE / TIMONERIE | O29: (+43DA) | P29: 43DA GMDSS STATION | Q29: 4032 | R29: WHEELHOUSE / TIMONERIE | S29: 4032S030X01N,4032S031X03N,4032S031X05N,4032S031X06N,4032P031X01N | T29: LOCAL | U29: WK39/2024 NEW CABLE | V29: 4032S030X01N | W29: 4032P031X01N
A30: 721 | B30: 721W0025 | C30: 1 | D30: 1 | G30: C+SH 3X1.5 | H30: S1 | I30: 15.06 | J30: =ROUNDUP(I30,0) -> 16 | K30: (+16NA) | L30: "16NA" 230VAC NAUTICAL DISTRIBUTION PANEL | M30: 4032 | N30: WHEELHOUSE / TIMONERIE | O30: (+43DA) | P30: 43DA GMDSS STATION | Q30: 4032 | R30: WHEELHOUSE / TIMONERIE | S30: 4032S030X01N,4032S031X03N,4032S031X05N,4032S031X06N,4032P031X01N | T30: LOCAL | U30: WK39/2024 NEW CABLE | V30: 4032S030X01N | W30: 4032P031X01N
A31: 721 | B31: 721W0028 | C31: 1 | D31: 1 | G31: COAX_RG214 | H31: S3 | I31: 44.06 | J31: =ROUNDUP(I31,0) -> 45 | K31: (+43DA) | L31: 43DA GMDSS STATION | M31: 4032 | N31: WHEELHOUSE / TIMONERIE | O31: (=721++4068+-721U21) | P31: MF/HF KUM803MWM W/R RX ANTENNA | Q31: 4068 | R31: MAST STEP / PIED DE MAT | S31: 4032P031X01N,4032S031X06N,4032S031X05N,404044030S11,414333028S11,415133024S11,4151S022X01N,4151S020X01N,4155S016X01N,4155S015X03N,4155S016X08N,5010S016X06G | T31: NOT LOCAL CABLE | U31: WK39/2024 NEW CABLE | V31: 4032P031X01N | W31: 5010S016X06G
A32: 721 | B32: 721W0029 | G32: ORIGINAL CABLE 7X | H32: S2 | I32: 41.52 | J32: =ROUNDUP(I32,0) -> 42 | K32: (+43DA) | L32: 43DA GMDSS STATION | M32: 4032 | N32: WHEELHOUSE / TIMONERIE | O32: (=721++5010+-721U20) | P32: MF/HF FURUNO AT-5075 | Q32: 5010 | R32: TOP DECK / TOIT | S32: 4032P031X01N,4032S031X06N,4032S031X05N,404044030S11,404044028P12,4242P028X04N,4242P023X01N,4258P017X01N,5010P015X05G | T32: NOT LOCAL CABLE | U32: WK39/2024 NEW CABLE | V32: 4032P031X01N | W32: 5010P015X05G
A33: 721 | B33: 721W0030 | C33: 1 | D33: 1 | G33: COAX_RG214 | H33: S3 | I33: 41.52 | J33: =ROUNDUP(I33,0) -> 42 | K33: (+43DA) | L33: 43DA GMDSS STATION | M33: 4032 | N33: WHEELHOUSE / TIMONERIE | O33: (=721++5010+-721U20) | P33: MF/HF FURUNO AT-5075 | Q33: 5010 | R33: TOP DECK / TOIT | S33: 4032P031X01N,4032S031X06N,4032S031X05N,404044030S11,404044028P12,4242P028X04N,4242P023X01N,4258P017X01N,5010P015X10G | T33: NOT LOCAL CABLE | U33: WK39/2024 NEW CABLE | V33: 4032P031X01N | W33: 5010P015X10G
